Workbook

Sheet CorST
A1: Word | B1: Частота-CorST | C1: IPM-CorST | D1: Ранг-CorST | E1: сколько раз встречается в столбце | F1: номер строки в rlc | G1: IPM_rlc
A2: в | B2: 35889 | C2: 11520.564 | D2: 1 | E2: =COUNTIF(B:B,B2) -> 1 | F2: =MATCH(A2,RLC!A:A,0) -> 3 | G2: {=INDEX(RLC!C:C,CorST!F2)} -> 37993.234
A3: и | B3: 31435 | C3: 10090.806 | D3: =D2+IF(B3<>B2,E2,0) -> 2 | E3: =COUNTIF(B:B,B3) -> 1 | F3: =MATCH(A3,RLC!A:A,0) -> 2 | G3: {=INDEX(RLC!C:C,CorST!F3)} -> 38334.702
A4: на | B4: 13212 | C4: 4241.1239 | D4: =D3+IF(B4<>B3,E3,0) -> 3 | E4: =COUNTIF(B:B,B4) -> 1 | F4: =MATCH(A4,RLC!A:A,0) -> 5 | G4: {=INDEX(RLC!C:C,CorST!F4)} -> 13265.412
A5: не | B5: 11811 | C5: 3791.3953 | D5: =D4+IF(B5<>B4,E4,0) -> 4 | E5: =COUNTIF(B:B,B5) -> 1 | F5: =MATCH(A5,RLC!A:A,0) -> 6 | G5: {=INDEX(RLC!C:C,CorST!F5)} -> 12860.168
A6: с | B6: 11363 | C6: 3647.5848 | D6: =D5+IF(B6<>B5,E5,0) -> 5 | E6: =COUNTIF(B:B,B6) -> 1 | F6: =MATCH(A6,RLC!A:A,0) -> 8 | G6: {=INDEX(RLC!C:C,CorST!F6)} -> 9178.432
A7: что | B7: 10265 | C7: 3295.1208 | D7: =D6+IF(B7<>B6,E6,0) -> 6 | E7: =COUNTIF(B:B,B7) -> 1 | F7: =MATCH(A7,RLC!A:A,0) -> 4 | G7: {=INDEX(RLC!C:C,CorST!F7)} -> 16305.402
A8: как | B8: 7396 | C8: 2374.1562 | D8: =D7+IF(B8<>B7,E7,0) -> 7 | E8: =COUNTIF(B:B,B8) -> 1 | F8: =MATCH(A8,RLC!A:A,0) -> 9 | G8: {=INDEX(RLC!C:C,CorST!F8)} -> 8273.6097
A9: к | B9: 6790 | C9: 2179.6269 | D9: =D8+IF(B9<>B8,E8,0) -> 8 | E9: =COUNTIF(B:B,B9) -> 1 | F9: =MATCH(A9,RLC!A:A,0) -> 15 | G9: {=INDEX(RLC!C:C,CorST!F9)} -> 4742.0127
A10: а | B10: 5924 | C10: 1901.6362 | D10: =D9+IF(B10<>B9,E9,0) -> 9 | E10: =COUNTIF(B:B,B10) -> 1 | F10: =MATCH(A10,RLC!A:A,0) -> 20 | G10: {=INDEX(RLC!C:C,CorST!F10)} -> 3449.2197
A11: для | B11: 5652 | C11: 1814.3227 | D11: =D10+IF(B11<>B10,E10,0) -> 10 | E11: =COUNTIF(B:B,B11) -> 1 | F11: =MATCH(A11,RLC!A:A,0) -> 14 | G11: {=INDEX(RLC!C:C,CorST!F11)} -> 5009.0748
A12: по | B12: 5634 | C12: 1808.5447 | D12: =D11+IF(B12<>B11,E11,0) -> 11 | E12: =COUNTIF(B:B,B12) -> 1 | F12: =MATCH(A12,RLC!A:A,0) -> 16 | G12: {=INDEX(RLC!C:C,CorST!F12)} -> 4641.034
A13: о | B13: 4912 | C13: 1576.7787 | D13: =D12+IF(B13<>B12,E12,0) -> 12 | E13: =COUNTIF(B:B,B13) -> 1 | F13: =MATCH(A13,RLC!A:A,0) -> 13 | G13: {=INDEX(RLC!C:C,CorST!F13)} -> 5022.3615
A14: из | B14: 4365 | C14: 1401.1887 | D14: =D13+IF(B14<>B13,E13,0) -> 13 | E14: =COUNTIF(B:B,B14) -> 1 | F14: =MATCH(A14,RLC!A:A,0) -> 17 | G14: {=INDEX(RLC!C:C,CorST!F14)} -> 4432.4333
... A1349: форм | B1349: 92 | C1349: 29.532501 | D1349: =D1348+IF(B1349<>B1348,E1348,0) -> 1326 | E1349: =COUNTIF(B:B,B1349) -> 26 | F1349: =MATCH(A1349,RLC!A:A,0) -> 5289 | G1349: {=INDEX(RLC!C:C,CorST!F1349)} -> 21.258673
A1350: школе | B1350: 92 | C1350: 29.532501 | D1350: =D1349+IF(B1350<>B1349,E1349,0) -> 1326 | E1350: =COUNTIF(B:B,B1350) -> 26 | F1350: =MATCH(A1350,RLC!A:A,0) -> 404 | G1350: {=INDEX(RLC!C:C,CorST!F1350)} -> 259.09008 | H1350: =C1350>F1350 -> FALSE
A1351: элементов | B1351: 92 | C1351: 29.532501 | D1351: =D1350+IF(B1351<>B1350,E1350,0) -> 1326 | E1351: =COUNTIF(B:B,B1351) -> 26 | F1351: =MATCH(A1351,RLC!A:A,0) -> 4112 | G1351: {=INDEX(RLC!C:C,CorST!F1351)} -> 27.902008
A1352: этими | B1352: 92 | C1352: 29.532501 | D1352: =D1351+IF(B1352<>B1351,E1351,0) -> 1326 | E1352: =COUNTIF(B:B,B1352) -> 26 | F1352: =MATCH(A1352,RLC!A:A,0) -> 1492 | G1352: {=INDEX(RLC!C:C,CorST!F1352)} -> 77.062689
A1353: артикля | B1353: 91 | C1353: 29.211495 | D1353: =D1352+IF(B1353<>B1352,E1352,0) -> 1352 | E1353: =COUNTIF(B:B,B1353) -> 12 | F1353: =MATCH(A1353,RLC!A:A,0) -> #N/A | G1353: {=INDEX(RLC!C:C,CorST!F1353)} -> #N/A
A1354: всему | B1354: 91 | C1354: 29.211495 | D1354: =D1353+IF(B1354<>B1353,E1353,0) -> 1352 | E1354: =COUNTIF(B:B,B1354) -> 12 | F1354: =MATCH(A1354,RLC!A:A,0) -> 741 | G1354: {=INDEX(RLC!C:C,CorST!F1354)} -> 144.82471
A1355: выполнения | B1355: 91 | C1355: 29.211495 | D1355: =D1354+IF(B1355<>B1354,E1354,0) -> 1352 | E1355: =COUNTIF(B:B,B1355) -> 12 | F1355: =MATCH(A1355,RLC!A:A,0) -> #N/A | G1355: {=INDEX(RLC!C:C,CorST!F1355)} -> #N/A
A1356: достоевский | B1356: 91 | C1356: 29.211495 | D1356: =D1355+IF(B1356<>B1355,E1355,0) -> 1352 | E1356: =COUNTIF(B:B,B1356) -> 12 | F1356: =MATCH(A1356,RLC!A:A,0) -> #N/A | G1356: {=INDEX(RLC!C:C,CorST!F1356)} -> #N/A
A1357: менеджмента | B1357: 91 | C1357: 29.211495 | D1357: =D1356+IF(B1357<>B1356,E1356,0) -> 1352 | E1357: =COUNTIF(B:B,B1357) -> 12 | F1357: =MATCH(A1357,RLC!A:A,0) -> 2858 | G1357: {=INDEX(RLC!C:C,CorST!F1357)} -> 39.860012
A1358: наша | B1358: 91 | C1358: 29.211495 | D1358: =D1357+IF(B1358<>B1357,E1357,0) -> 1352 | E1358: =COUNTIF(B:B,B1358) -> 12 | F1358: =MATCH(A1358,RLC!A:A,0) -> 551 | G1358: {=INDEX(RLC!C:C,CorST!F1358)} -> 193.98539
A1359: поднятая | B1359: 91 | C1359: 29.211495 | D1359: =D1358+IF(B1359<>B1358,E1358,0) -> 1352 | E1359: =COUNTIF(B:B,B1359) -> 12 | F1359: =MATCH(A1359,RLC!A:A,0) -> #N/A | G1359: {=INDEX(RLC!C:C,CorST!F1359)} -> #N/A
A1360: постепенно | B1360: 91 | C1360: 29.211495 | D1360: =D1359+IF(B1360<>B1359,E1359,0) -> 1352 | E1360: =COUNTIF(B:B,B1360) -> 12 | F1360: =MATCH(A1360,RLC!A:A,0) -> 2469 | G1360: {=INDEX(RLC!C:C,CorST!F1360)} -> 46.503347
A1361: рублей | B1361: 91 | C1361: 29.211495 | D1361: =D1360+IF(B1361<>B1360,E1360,0) -> 1352 | E1361: =COUNTIF(B:B,B1361) -> 12 | F1361: =MATCH(A1361,RLC!A:A,0) -> 1697 | G1361: {=INDEX(RLC!C:C,CorST!F1361)} -> 67.76202
A1362: сегодняшний | B1362: 91 | C1362: 29.211495 | D1362: =D1361+IF(B1362<>B1361,E1361,0) -> 1352 | E1362: =COUNTIF(B:B,B1362) -> 12 | F1362: =MATCH(A1362,RLC!A:A,0) -> 1873 | G1362: {=INDEX(RLC!C:C,CorST!F1362)} -> 62.447352
... A1716: чехов | B1716: 73 | C1716: 23.433397 | D1716: =D1715+IF(B1716<>B1715,E1715,0) -> 1684 | E1716: =COUNTIF(B:B,B1716) -> 35 | F1716: =MATCH(A1716,RLC!A:A,0) -> #N/A | G1716: {=INDEX(RLC!C:C,CorST!F1716)} -> #N/A
A1717: шапочка | B1717: 73 | C1717: 23.433397 | D1717: =D1716+IF(B1717<>B1716,E1716,0) -> 1684 | E1717: =COUNTIF(B:B,B1717) -> 35 | F1717: =MATCH(A1717,RLC!A:A,0) -> 3340 | G1717: {=INDEX(RLC!C:C,CorST!F1717)} -> 34.545343 | H1717: =C1717>F1717 -> FALSE
A1718: широко | B1718: 73 | C1718: 23.433397 | D1718: =D1717+IF(B1718<>B1717,E1717,0) -> 1684 | E1718: =COUNTIF(B:B,B1718) -> 35 | F1718: =MATCH(A1718,RLC!A:A,0) -> 1585 | G1718: {=INDEX(RLC!C:C,CorST!F1718)} -> 73.076688 | H1718: =C1718>F1718 -> FALSE
A1719: эмоций | B1719: 73 | C1719: 23.433397 | D1719: =D1718+IF(B1719<>B1718,E1718,0) -> 1684 | E1719: =COUNTIF(B:B,B1719) -> 35 | F1719: =MATCH(A1719,RLC!A:A,0) -> 6913 | G1719: {=INDEX(RLC!C:C,CorST!F1719)} -> 15.944005
A1720: большие | B1720: 72 | C1720: 23.112392 | D1720: =D1719+IF(B1720<>B1719,E1719,0) -> 1719 | E1720: =COUNTIF(B:B,B1720) -> 42 | F1720: =MATCH(A1720,RLC!A:A,0) -> 837 | G1720: {=INDEX(RLC!C:C,CorST!F1720)} -> 128.8807
A1721: большого | B1721: 72 | C1721: 23.112392 | D1721: =D1720+IF(B1721<>B1720,E1720,0) -> 1719 | E1721: =COUNTIF(B:B,B1721) -> 42 | F1721: =MATCH(A1721,RLC!A:A,0) -> 2651 | G1721: {=INDEX(RLC!C:C,CorST!F1721)} -> 42.517346
A1722: ведет | B1722: 72 | C1722: 23.112392 | D1722: =D1721+IF(B1722<>B1721,E1721,0) -> 1719 | E1722: =COUNTIF(B:B,B1722) -> 42 | F1722: =MATCH(A1722,RLC!A:A,0) -> 3483 | G1722: {=INDEX(RLC!C:C,CorST!F1722)} -> 31.888009
A1723: вниз | B1723: 72 | C1723: 23.112392 | D1723: =D1722+IF(B1723<>B1722,E1722,0) -> 1719 | E1723: =COUNTIF(B:B,B1723) -> 42 | F1723: =MATCH(A1723,RLC!A:A,0) -> 2832 | G1723: {=INDEX(RLC!C:C,CorST!F1723)} -> 39.860012
A1724: вузов | B1724: 72 | C1724: 23.112392 | D1724: =D1723+IF(B1724<>B1723,E1723,0) -> 1719 | E1724: =COUNTIF(B:B,B1724) -> 42 | F1724: =MATCH(A1724,RLC!A:A,0) -> 6052 | G1724: {=INDEX(RLC!C:C,CorST!F1724)} -> 17.272672
A1725: выражений | B1725: 72 | C1725: 23.112392 | D1725: =D1724+IF(B1725<>B1724,E1724,0) -> 1719 | E1725: =COUNTIF(B:B,B1725) -> 42 | F1725: =MATCH(A1725,RLC!A:A,0) -> 3786 | G1725: {=INDEX(RLC!C:C,CorST!F1725)} -> 29.230675
A1726: гражданским | B1726: 72 | C1726: 23.112392 | D1726: =D1725+IF(B1726<>B1725,E1725,0) -> 1719 | E1726: =COUNTIF(B:B,B1726) -> 42 | F1726: =MATCH(A1726,RLC!A:A,0) -> #N/A | G1726: {=INDEX(RLC!C:C,CorST!F1726)} -> #N/A
A1727: изучить | B1727: 72 | C1727: 23.112392 | D1727: =D1726+IF(B1727<>B1726,E1726,0) -> 1719 | E1727: =COUNTIF(B:B,B1727) -> 42 | F1727: =MATCH(A1727,RLC!A:A,0) -> 4372 | G1727: {=INDEX(RLC!C:C,CorST!F1727)} -> 25.244674
...

Sheet корст с рлс
A1: Word | B1: Частота-CorST | C1: IPM-CorST | D1: Ранг-CorST | E1: сколько раз встречается в столбце | F1: номер строки в rlc | G1: IPM_rlc
A2: в | B2: 35889 | C2: 11520.564 | D2: 1 | E2: =COUNTIF(B:B,B2) -> 1 | F2: =MATCH(A2,RLC!A:A,0) -> 3 | G2: {=INDEX(RLC!C:C,CorST!F2)} -> 37993.234
A3: и | B3: 31435 | C3: 10090.806 | D3: =D2+IF(B3<>B2,E2,0) -> 2 | E3: =COUNTIF(B:B,B3) -> 1 | F3: =MATCH(A3,RLC!A:A,0) -> 2 | G3: {=INDEX(RLC!C:C,CorST!F3)} -> 38334.702
A4: на | B4: 13212 | C4: 4241.1239 | D4: =D3+IF(B4<>B3,E3,0) -> 3 | E4: =COUNTIF(B:B,B4) -> 1 | F4: =MATCH(A4,RLC!A:A,0) -> 5 | G4: {=INDEX(RLC!C:C,CorST!F4)} -> 13265.412
A5: не | B5: 11811 | C5: 3791.3953 | D5: =D4+IF(B5<>B4,E4,0) -> 4 | E5: =COUNTIF(B:B,B5) -> 1 | F5: =MATCH(A5,RLC!A:A,0) -> 6 | G5: {=INDEX(RLC!C:C,CorST!F5)} -> 12860.168
A6: с | B6: 11363 | C6: 3647.5848 | D6: =D5+IF(B6<>B5,E5,0) -> 5 | E6: =COUNTIF(B:B,B6) -> 1 | F6: =MATCH(A6,RLC!A:A,0) -> 8 | G6: {=INDEX(RLC!C:C,CorST!F6)} -> 9178.432
A7: что | B7: 10265 | C7: 3295.1208 | D7: =D6+IF(B7<>B6,E6,0) -> 6 | E7: =COUNTIF(B:B,B7) -> 1 | F7: =MATCH(A7,RLC!A:A,0) -> 4 | G7: {=INDEX(RLC!C:C,CorST!F7)} -> 16305.402
A8: как | B8: 7396 | C8: 2374.1562 | D8: =D7+IF(B8<>B7,E7,0) -> 7 | E8: =COUNTIF(B:B,B8) -> 1 | F8: =MATCH(A8,RLC!A:A,0) -> 9 | G8: {=INDEX(RLC!C:C,CorST!F8)} -> 8273.6097
A9: к | B9: 6790 | C9: 2179.6269 | D9: =D8+IF(B9<>B8,E8,0) -> 8 | E9: =COUNTIF(B:B,B9) -> 1 | F9: =MATCH(A9,RLC!A:A,0) -> 15 | G9: {=INDEX(RLC!C:C,CorST!F9)} -> 4742.0127
A10: а | B10: 5924 | C10: 1901.6362 | D10: =D9+IF(B10<>B9,E9,0) -> 9 | E10: =COUNTIF(B:B,B10) -> 1 | F10: =MATCH(A10,RLC!A:A,0) -> 20 | G10: {=INDEX(RLC!C:C,CorST!F10)} -> 3449.2197
A11: для | B11: 5652 | C11: 1814.3227 | D11: =D10+IF(B11<>B10,E10,0) -> 10 | E11: =COUNTIF(B:B,B11) -> 1 | F11: =MATCH(A11,RLC!A:A,0) -> 14 | G11: {=INDEX(RLC!C:C,CorST!F11)} -> 5009.0748
A12: по | B12: 5634 | C12: 1808.5447 | D12: =D11+IF(B12<>B11,E11,0) -> 11 | E12: =COUNTIF(B:B,B12) -> 1 | F12: =MATCH(A12,RLC!A:A,0) -> 16 | G12: {=INDEX(RLC!C:C,CorST!F12)} -> 4641.034
A13: о | B13: 4912 | C13: 1576.7787 | D13: =D12+IF(B13<>B12,E12,0) -> 12 | E13: =COUNTIF(B:B,B13) -> 1 | F13: =MATCH(A13,RLC!A:A,0) -> 13 | G13: {=INDEX(RLC!C:C,CorST!F13)} -> 5022.3615
A14: из | B14: 4365 | C14: 1401.1887 | D14: =D13+IF(B14<>B13,E13,0) -> 13 | E14: =COUNTIF(B:B,B14) -> 1 | F14: =MATCH(A14,RLC!A:A,0) -> 17 | G14: {=INDEX(RLC!C:C,CorST!F14)} -> 4432.4333
... A1349: форм | B1349: 92 | C1349: 29.532501 | D1349: =D1348+IF(B1349<>B1348,E1348,0) -> 1326 | E1349: =COUNTIF(B:B,B1349) -> 26 | F1349: =MATCH(A1349,RLC!A:A,0) -> 5289 | G1349: {=INDEX(RLC!C:C,CorST!F1349)} -> 21.258673
A1350: школе | B1350: 92 | C1350: 29.532501 | D1350: =D1349+IF(B1350<>B1349,E1349,0) -> 1326 | E1350: =COUNTIF(B:B,B1350) -> 26 | F1350: =MATCH(A1350,RLC!A:A,0) -> 404 | G1350: {=INDEX(RLC!C:C,CorST!F1350)} -> 259.09008 | H1350: =C1350>F1350 -> FALSE
A1351: элементов | B1351: 92 | C1351: 29.532501 | D1351: =D1350+IF(B1351<>B1350,E1350,0) -> 1326 | E1351: =COUNTIF(B:B,B1351) -> 26 | F1351: =MATCH(A1351,RLC!A:A,0) -> 4112 | G1351: {=INDEX(RLC!C:C,CorST!F1351)} -> 27.902008
A1352: этими | B1352: 92 | C1352: 29.532501 | D1352: =D1351+IF(B1352<>B1351,E1351,0) -> 1326 | E1352: =COUNTIF(B:B,B1352) -> 26 | F1352: =MATCH(A1352,RLC!A:A,0) -> 1492 | G1352: {=INDEX(RLC!C:C,CorST!F1352)} -> 77.062689
A1353: артикля | B1353: 91 | C1353: 29.211495 | D1353: =D1352+IF(B1353<>B1352,E1352,0) -> 1352 | E1353: =COUNTIF(B:B,B1353) -> 12 | F1353: =MATCH(A1353,RLC!A:A,0) -> #N/A | G1353: {=INDEX(RLC!C:C,CorST!F1353)} -> #N/A
A1354: всему | B1354: 91 | C1354: 29.211495 | D1354: =D1353+IF(B1354<>B1353,E1353,0) -> 1352 | E1354: =COUNTIF(B:B,B1354) -> 12 | F1354: =MATCH(A1354,RLC!A:A,0) -> 741 | G1354: {=INDEX(RLC!C:C,CorST!F1354)} -> 144.82471
A1355: выполнения | B1355: 91 | C1355: 29.211495 | D1355: =D1354+IF(B1355<>B1354,E1354,0) -> 1352 | E1355: =COUNTIF(B:B,B1355) -> 12 | F1355: =MATCH(A1355,RLC!A:A,0) -> #N/A | G1355: {=INDEX(RLC!C:C,CorST!F1355)} -> #N/A
A1356: достоевский | B1356: 91 | C1356: 29.211495 | D1356: =D1355+IF(B1356<>B1355,E1355,0) -> 1352 | E1356: =COUNTIF(B:B,B1356) -> 12 | F1356: =MATCH(A1356,RLC!A:A,0) -> #N/A | G1356: {=INDEX(RLC!C:C,CorST!F1356)} -> #N/A
A1357: менеджмента | B1357: 91 | C1357: 29.211495 | D1357: =D1356+IF(B1357<>B1356,E1356,0) -> 1352 | E1357: =COUNTIF(B:B,B1357) -> 12 | F1357: =MATCH(A1357,RLC!A:A,0) -> 2858 | G1357: {=INDEX(RLC!C:C,CorST!F1357)} -> 39.860012
A1358: наша | B1358: 91 | C1358: 29.211495 | D1358: =D1357+IF(B1358<>B1357,E1357,0) -> 1352 | E1358: =COUNTIF(B:B,B1358) -> 12 | F1358: =MATCH(A1358,RLC!A:A,0) -> 551 | G1358: {=INDEX(RLC!C:C,CorST!F1358)} -> 193.98539
A1359: поднятая | B1359: 91 | C1359: 29.211495 | D1359: =D1358+IF(B1359<>B1358,E1358,0) -> 1352 | E1359: =COUNTIF(B:B,B1359) -> 12 | F1359: =MATCH(A1359,RLC!A:A,0) -> #N/A | G1359: {=INDEX(RLC!C:C,CorST!F1359)} -> #N/A
A1360: постепенно | B1360: 91 | C1360: 29.211495 | D1360: =D1359+IF(B1360<>B1359,E1359,0) -> 1352 | E1360: =COUNTIF(B:B,B1360) -> 12 | F1360: =MATCH(A1360,RLC!A:A,0) -> 2469 | G1360: {=INDEX(RLC!C:C,CorST!F1360)} -> 46.503347
A1361: рублей | B1361: 91 | C1361: 29.211495 | D1361: =D1360+IF(B1361<>B1360,E1360,0) -> 1352 | E1361: =COUNTIF(B:B,B1361) -> 12 | F1361: =MATCH(A1361,RLC!A:A,0) -> 1697 | G1361: {=INDEX(RLC!C:C,CorST!F1361)} -> 67.76202
A1362: сегодняшний | B1362: 91 | C1362: 29.211495 | D1362: =D1361+IF(B1362<>B1361,E1361,0) -> 1352 | E1362: =COUNTIF(B:B,B1362) -> 12 | F1362: =MATCH(A1362,RLC!A:A,0) -> 1873 | G1362: {=INDEX(RLC!C:C,CorST!F1362)} -> 62.447352
... A1716: чехов | B1716: 73 | C1716: 23.433397 | D1716: =D1715+IF(B1716<>B1715,E1715,0) -> 1684 | E1716: =COUNTIF(B:B,B1716) -> 35 | F1716: =MATCH(A1716,RLC!A:A,0) -> #N/A | G1716: {=INDEX(RLC!C:C,CorST!F1716)} -> #N/A
A1717: шапочка | B1717: 73 | C1717: 23.433397 | D1717: =D1716+IF(B1717<>B1716,E1716,0) -> 1684 | E1717: =COUNTIF(B:B,B1717) -> 35 | F1717: =MATCH(A1717,RLC!A:A,0) -> 3340 | G1717: {=INDEX(RLC!C:C,CorST!F1717)} -> 34.545343 | H1717: =C1717>F1717 -> FALSE
A1718: широко | B1718: 73 | C1718: 23.433397 | D1718: =D1717+IF(B1718<>B1717,E1717,0) -> 1684 | E1718: =COUNTIF(B:B,B1718) -> 35 | F1718: =MATCH(A1718,RLC!A:A,0) -> 1585 | G1718: {=INDEX(RLC!C:C,CorST!F1718)} -> 73.076688 | H1718: =C1718>F1718 -> FALSE
A1719: эмоций | B1719: 73 | C1719: 23.433397 | D1719: =D1718+IF(B1719<>B1718,E1718,0) -> 1684 | E1719: =COUNTIF(B:B,B1719) -> 35 | F1719: =MATCH(A1719,RLC!A:A,0) -> 6913 | G1719: {=INDEX(RLC!C:C,CorST!F1719)} -> 15.944005
A1720: большие | B1720: 72 | C1720: 23.112392 | D1720: =D1719+IF(B1720<>B1719,E1719,0) -> 1719 | E1720: =COUNTIF(B:B,B1720) -> 42 | F1720: =MATCH(A1720,RLC!A:A,0) -> 837 | G1720: {=INDEX(RLC!C:C,CorST!F1720)} -> 128.8807
A1721: большого | B1721: 72 | C1721: 23.112392 | D1721: =D1720+IF(B1721<>B1720,E1720,0) -> 1719 | E1721: =COUNTIF(B:B,B1721) -> 42 | F1721: =MATCH(A1721,RLC!A:A,0) -> 2651 | G1721: {=INDEX(RLC!C:C,CorST!F1721)} -> 42.517346
A1722: ведет | B1722: 72 | C1722: 23.112392 | D1722: =D1721+IF(B1722<>B1721,E1721,0) -> 1719 | E1722: =COUNTIF(B:B,B1722) -> 42 | F1722: =MATCH(A1722,RLC!A:A,0) -> 3483 | G1722: {=INDEX(RLC!C:C,CorST!F1722)} -> 31.888009
A1723: вниз | B1723: 72 | C1723: 23.112392 | D1723: =D1722+IF(B1723<>B1722,E1722,0) -> 1719 | E1723: =COUNTIF(B:B,B1723) -> 42 | F1723: =MATCH(A1723,RLC!A:A,0) -> 2832 | G1723: {=INDEX(RLC!C:C,CorST!F1723)} -> 39.860012
A1724: вузов | B1724: 72 | C1724: 23.112392 | D1724: =D1723+IF(B1724<>B1723,E1723,0) -> 1719 | E1724: =COUNTIF(B:B,B1724) -> 42 | F1724: =MATCH(A1724,RLC!A:A,0) -> 6052 | G1724: {=INDEX(RLC!C:C,CorST!F1724)} -> 17.272672
A1725: выражений | B1725: 72 | C1725: 23.112392 | D1725: =D1724+IF(B1725<>B1724,E1724,0) -> 1719 | E1725: =COUNTIF(B:B,B1725) -> 42 | F1725: =MATCH(A1725,RLC!A:A,0) -> 3786 | G1725: {=INDEX(RLC!C:C,CorST!F1725)} -> 29.230675
A1726: гражданским | B1726: 72 | C1726: 23.112392 | D1726: =D1725+IF(B1726<>B1725,E1725,0) -> 1719 | E1726: =COUNTIF(B:B,B1726) -> 42 | F1726: =MATCH(A1726,RLC!A:A,0) -> #N/A | G1726: {=INDEX(RLC!C:C,CorST!F1726)} -> #N/A
A1727: изучить | B1727: 72 | C1727: 23.112392 | D1727: =D1726+IF(B1727<>B1726,E1726,0) -> 1719 | E1727: =COUNTIF(B:B,B1727) -> 42 | F1727: =MATCH(A1727,RLC!A:A,0) -> 4372 | G1727: {=INDEX(RLC!C:C,CorST!F1727)} -> 25.244674
...

Sheet merge
A1: Word | B1: IPM-CorST | C1: IPM_rlc
A2: а | B2: 1901.6362 | C2: 3449.2197
A3: аббревиатуры | B3: 4.4940762
A4: абзац | B4: 86.029458 | C4: 75.734022
A5: абзаца | B5: 51.039865
A6: абзаце | B6: 43.014729 | C6: 23.916007
A7: абзацев | B7: 12.198207
A8: абзацу | B8: 3.5310598
A9: абзацы | B9: 43.65674
A10: абитуриентов | B10: 3.2100544 | C10: 27.902008
A11: абитуриенты | C11: 15.944005
A12: абрамова | B12: 3.2100544
A13: абсолютно | B13: 35.631604 | C13: 81.04869
A14: абсолютной | B14: 4.1730707
A15: абстрагироваться | B15: 5.4570925
A16: абстрактного | B16: 6.7411142
A17: абстрактное | B17: 13.803234
A18: абстрактном | B18: 3.5310598
A19: абстрактные | B19: 8.6671469 | C19: 14.615338
A20: абстрактный | B20: 4.1730707
A21: абстрактным | B21: 6.0991034
A22: абстрактными | B22: 3.2100544
A23: абстрактных | B23: 5.4570925
A24: абсурд | B24: 3.2100544
A25: абсурда | B25: 9.3091578 | C25: 13.286671
A26: авангард | C26: 14.615338
A27: авангарда | C27: 43.846013
A28: авангардистов | C28: 15.944005
A29: авангардные | C29: 15.944005
A30: аварии | C30: 38.531345
A31: авария | C31: 14.615338
A32: август | B32: 18.29731
A33: августа | B33: 25.680435 | C33: 57.132683
A34: августе | C34: 13.286671
A35: австрийский | B35: 6.4201088
A36: австрийского | B36: 5.4570925
A37: автобиографическое | B37: 4.8150816
A38: автобиография | B38: 3.2100544
A39: автобус | B39: 3.8520653 | C39: 14.615338
A40: автобусе | C40: 17.272672
...

Sheet RLC
A1: Word | B1: Частота-RLC | C1: IPM-RLC | D1: Ранг-RLC | E1: сколько раз встречается число в столбце | F1: номер строки в CorST
A2: и | B2: 28852 | C2: 38334.702 | D2: 1 | E2: =COUNTIF(B:B,B2) -> 1 | F2: =MATCH(A2,CorST!A:A,0) -> 3
A3: в | B3: 28595 | C3: 37993.234 | D3: =D2+IF(B3<>B2,E2,0) -> 2 | E3: =COUNTIF(B:B,B3) -> 1 | F3: =MATCH(A3,CorST!A:A,0) -> 2
A4: что | B4: 12272 | C4: 16305.402 | D4: =D3+IF(B4<>B3,E3,0) -> 3 | E4: =COUNTIF(B:B,B4) -> 1 | F4: =MATCH(A4,CorST!A:A,0) -> 7
A5: на | B5: 9984 | C5: 13265.412 | D5: =D4+IF(B5<>B4,E4,0) -> 4 | E5: =COUNTIF(B:B,B5) -> 1 | F5: =MATCH(A5,CorST!A:A,0) -> 4
A6: не | B6: 9679 | C6: 12860.168 | D6: =D5+IF(B6<>B5,E5,0) -> 5 | E6: =COUNTIF(B:B,B6) -> 1 | F6: =MATCH(A6,CorST!A:A,0) -> 5
A7: я | B7: 8489 | C7: 11279.055 | D7: =D6+IF(B7<>B6,E6,0) -> 6 | E7: =COUNTIF(B:B,B7) -> 1 | F7: =MATCH(A7,CorST!A:A,0) -> 24
A8: с | B8: 6908 | C8: 9178.432 | D8: =D7+IF(B8<>B7,E7,0) -> 7 | E8: =COUNTIF(B:B,B8) -> 1 | F8: =MATCH(A8,CorST!A:A,0) -> 6
A9: как | B9: 6227 | C9: 8273.6097 | D9: =D8+IF(B9<>B8,E8,0) -> 8 | E9: =COUNTIF(B:B,B9) -> 1 | F9: =MATCH(A9,CorST!A:A,0) -> 8
A10: это | B10: 5389 | C10: 7160.1868 | D10: =D9+IF(B10<>B9,E9,0) -> 9 | E10: =COUNTIF(B:B,B10) -> 1 | F10: =MATCH(A10,CorST!A:A,0) -> 15
A11: но | B11: 4307 | C11: 5722.569 | D11: =D10+IF(B11<>B10,E10,0) -> 10 | E11: =COUNTIF(B:B,B11) -> 1 | F11: =MATCH(A11,CorST!A:A,0) -> 19
A12: он | B12: 4050 | C12: 5381.1016 | D12: =D11+IF(B12<>B11,E11,0) -> 11 | E12: =COUNTIF(B:B,B12) -> 1 | F12: =MATCH(A12,CorST!A:A,0) -> 21
A13: о | B13: 3780 | C13: 5022.3615 | D13: =D12+IF(B13<>B12,E12,0) -> 12 | E13: =COUNTIF(B:B,B13) -> 1 | F13: =MATCH(A13,CorST!A:A,0) -> 13
A14: для | B14: 3770 | C14: 5009.0748 | D14: =D13+IF(B14<>B13,E13,0) -> 13 | E14: =COUNTIF(B:B,B14) -> 1 | F14: =MATCH(A14,CorST!A:A,0) -> 11
... A8127: японский | B8127: 10 | C8127: 13.286671 | D8127: =D8126+IF(B8127<>B8126,E8126,0) -> 7471 | E8127: =COUNTIF(B:B,B8127) -> 656 | F8127: =MATCH(A8127,CorST!A:A,0) -> #N/A
